DEBUG | 2023-07-25 15:26:16,641 | Module: baecon_logger | Line: 33 
 	 :: a in __main__ called with args 0

ERROR | 2023-07-25 15:26:16,641 | Module: baecon_logger | Line: 38 
 	 :: Exception raised in a. exception: division by zero
Traceback (most recent call last):
  File "c:\Users\walsworth1\Documents\Jupyter_Notebooks\baecon\src\baecon\utils\baecon_logger.py", line 35, in wrapper
    result = func(*args, **kwargs)
  File "c:\Users\walsworth1\Documents\Jupyter_Notebooks\baecon\src\baecon\utils\baecon_logger.py", line 46, in a
    return 1 / x
ZeroDivisionError: division by zero
