DEBUG | 2023-07-25 15:34:17,740 | Module: baecon_logger | Line: 35 
 	 :: Method a(x) was called with args (0).
ERROR | 2023-07-25 15:34:17,741 | Module: baecon_logger | Line: 42 
 	 :: Exception raised in a. exception: division by zero
Traceback (most recent call last):
  File "c:\Users\walsworth1\Documents\Jupyter_Notebooks\baecon\src\baecon\utils\baecon_logger.py", line 39, in wrapper
    result = func(*args, **kwargs)
  File "c:\Users\walsworth1\Documents\Jupyter_Notebooks\baecon\src\baecon\utils\baecon_logger.py", line 50, in a
    return 1 / x
ZeroDivisionError: division by zero
